<?xml version="1.0"?>
<sdf version="1.7">
  <model name="robo_camuflado">
    <!-- Base Links -->
    <link name="base_footprint">
    
      <inertial>
        <mass>0.001</mass>
        <inertia>
          <ixx>1e-6</ixx><iyy>1e-6</iyy><izz>1e-6</izz>
          <ixy>0</ixy><ixz>0</ixz><iyz>0</iyz>
        </inertia>
      </inertial>
      <collision name="collision">
        <geometry>
          <box>
            <size>0.01 0.01 0.01</size>
          </box>
        </geometry>
      </collision>
    </link>


    <link name="base_link">
      
      <visual name="base_visual">
        <pose>-0.064 0 0 0 0 0</pose>
        <geometry>
          <mesh>
            <uri>file:///home/ruben/Documents/ProjetoFinal/roboauto/models/robo_camuflado/meshes/base_link.dae</uri>
            <scale>1 1 1</scale>
          </mesh>
        </geometry>
      </visual>
      <collision name="base_collision">
        <pose>-0.064 0 0.048 0 0 0</pose>
        <geometry>
          <box>
            <size>0.6 0.4 0.1</size> 
          </box>
        </geometry>
      </collision>
      <inertial>
        <mass>5.0</mass>
        <inertia>
          <ixx>0.1</ixx>
          <ixy>0</ixy>
          <ixz>0</ixz>
          <iyy>0.1</iyy>
          <iyz>0</iyz>
          <izz>0.1</izz>
        </inertia>
      </inertial>
    </link>
    <joint name="base_joint" type="fixed">
      <pose>0 0 0.01 0 0 0</pose>
      <parent>base_footprint</parent>
      <child>base_link</child>
    </joint>
    <!-- IMU -->
    <link name="imu_link">
      <sensor name="imu" type="imu">
        <always_on>1</always_on>
        <update_rate>200</update_rate>
        <visualize>true</visualize>
        <topic>imu</topic>
        <ignition_frame_id>imu_link</ignition_frame_id>
        <imu>
          <angular_velocity>
            <x><noise type="gaussian"><mean>0.0</mean><stddev>2e-4</stddev></noise></x>
            <y><noise type="gaussian"><mean>0.0</mean><stddev>2e-4</stddev></noise></y>
            <z><noise type="gaussian"><mean>0.0</mean><stddev>2e-4</stddev></noise></z>
          </angular_velocity>
          <linear_acceleration>
            <x><noise type="gaussian"><mean>0.0</mean><stddev>1.7e-2</stddev></noise></x>
            <y><noise type="gaussian"><mean>0.0</mean><stddev>1.7e-2</stddev></noise></y>
            <z><noise type="gaussian"><mean>0.0</mean><stddev>1.7e-2</stddev></noise></z>
          </linear_acceleration>
        </imu>
      </sensor>
    </link>
    <joint name="imu_joint" type="fixed">
      <pose>-0.032 0 0.068 0 0 0</pose>
      <parent>base_link</parent>
      <child>imu_link</child>
    </joint>

    <!-- CAMARA -->
    <link name="camera_link"/>
      <visual name="camera_visual">
        <geometry>
          <box>
            <size>0.05 0.05 0.05</size>
          </box>
        </geometry>
        <material>
          <ambient>0 1 0 1</ambient> <!-- green -->
          <diffuse>0 1 0 1</diffuse>
        </material>
      </visual>
    <joint name="camera_joint" type="fixed">
      <parent>base_link</parent>
      <child>camera_link</child>
      <pose>0 0 0 0 0 0</pose>
      <axis><xyz>0 0 1</xyz></axis>
    </joint>

    <link name="camera_rgb_frame">
      <inertial>
        <pose>0 0 0 0 0 0</pose>
        <inertia>
          <ixx>0.001</ixx><ixy>0.000</ixy><ixz>0.000</ixz>
          <iyy>0.001</iyy><iyz>0.000</iyz><izz>0.001</izz>
        </inertia>
        <mass>0.035</mass>
      </inertial>
      <pose>0 0 0 0 0 0</pose>
      <sensor name="camera" type="camera">
        <always_on>true</always_on>
        <visualize>true</visualize>
        <update_rate>30</update_rate>
        <camera_info_topic>/camera/rgb/camera_info</camera_info_topic>
        <topic>/camera/rgb/image_raw</topic>
        <ignition_frame_id>camera_rgb_frame</ignition_frame_id>
        <camera name="intel_realsense_r200">
          <horizontal_fov>1.02974</horizontal_fov>
          <image><width>1920</width><height>1080</height><format>R8G8B8</format></image>
          <clip><near>0.02</near><far>300</far></clip>
          <noise><type>gaussian</type><mean>0.0</mean><stddev>0.007</stddev></noise>
        </camera>
      </sensor>
    </link>
    <joint name="camera_rgb_joint" type="fixed">
      <parent>camera_link</parent>
      <child>camera_rgb_frame</child>
      <pose>0.1 0 0.35 0 0 0</pose> <!-- Modificado: à frente do LIDAR -->
      <axis><xyz>0 0 1</xyz></axis>
    </joint>

    <!-- LIDAR -->
    <link name="base_scan">
      <inertial>
        <pose>0 0 0 0 0 0</pose>
        <inertia><ixx>0.001</ixx><ixy>0</ixy><ixz>0</ixz><iyy>0.001</iyy><iyz>0</iyz><izz>0.001</izz></inertia>
        <mass>0.114</mass>
      </inertial>
      <collision name="lidar_sensor_collision">
        <pose>0 0 0 0 0 0</pose>
        <geometry>
          <cylinder><radius>0.0508</radius><length>0.055</length></cylinder>
        </geometry>
      </collision>
      <visual name="lidar_sensor_visual">
        <pose>0 0 0 0 0 0</pose>
        <geometry>
          <mesh> 
            <uri>model://robo_camuflado/meshes/lidar_link.dae</uri>
            <scale>1 1 1</scale>
          </mesh>
        </geometry>
        <material>
          <diffuse>0.145098039 0.156862745 0.164705882 1</diffuse>
          <ambient>0.145098039 0.156862745 0.164705882 1</ambient>
          <specular>0.145098039 0.156862745 0.164705882 1</specular>
        </material>
      </visual>
      <sensor name="gpu_lidar" type="gpu_lidar">
        <pose>0 0 0 0 0 0</pose>
        <topic>scan</topic>
        <ignition_frame_id>base_scan</ignition_frame_id>
        <update_rate>5</update_rate>
        <ray>
          <scan>
            <horizontal>
              <samples>360</samples>
              <resolution>1</resolution>
              <min_angle>0</min_angle>
              <max_angle>6.28</max_angle>
            </horizontal>
          </scan>
          <range>
            <min>0.120000</min>
            <max>20.0</max>
            <resolution>0.015000</resolution>
          </range>
          <noise>
            <type>gaussian</type>
            <mean>0.0</mean>
            <stddev>0.01</stddev>
          </noise>
        </ray>
        <always_on>true</always_on>
        <visualize>1</visualize>
      </sensor>
    </link>
    <joint name="lidar_joint" type="fixed">
      <pose>0 0 0.3 0 0 0</pose> <!-- Modificado: LIDAR no topo do robô -->
      <parent>base_link</parent>
      <child>base_scan</child>
    </joint>

    <!-- Front Left Wheel -->
    <link name="wheel_fl">
      <visual name="wheel_fl_visual">
        <geometry>
          <mesh>
            <uri>file:///home/ruben/Documents/ProjetoFinal/roboauto/models/robo_camuflado/meshes/wheel_fl.dae</uri>
            <scale>1 1 1</scale>
          </mesh>
        </geometry>
      </visual>
      <collision name="wheel_fl_collision">
        <geometry>
          <cylinder>
            <radius>0.3</radius> <!-- Adjust to match your wheel size -->
            <length>0.1</length>
          </cylinder>
        </geometry>
        <surface>
  <friction>
    <ode>
      <mu>1.0</mu>
      <mu2>1.0</mu2>
    </ode>
  </friction>
</surface>
      </collision>
      <inertial>
        <mass>0.5</mass>
        <inertia>
          <ixx>0.01</ixx>
          <ixy>0</ixy>
          <ixz>0</ixz>
          <iyy>0.01</iyy>
          <iyz>0</iyz>
          <izz>0.005</izz>
        </inertia>
      </inertial>
    </link>
    <!-- Front Right Wheel -->
    <link name="wheel_fr">
      <visual name="wheel_fr_visual">
        <geometry>
          <mesh>
            <uri>file:///home/ruben/Documents/ProjetoFinal/roboauto/models/robo_camuflado/meshes/wheel_fr.dae</uri>
            <scale>1 1 1</scale>
          </mesh>
        </geometry>
      </visual>
      <collision name="wheel_fr_collision">
        <geometry>
          <cylinder>
            <radius>0.3</radius>
            <length>0.1</length>
          </cylinder>
        </geometry>
        <surface>
          <friction>
            <ode>
              <mu>1.0</mu>
              <mu2>1.0</mu2>
            </ode>
          </friction>
        </surface>
      </collision>
      <inertial>
        <mass>0.5</mass>
        <inertia>
          <ixx>0.01</ixx>
          <ixy>0</ixy>
          <ixz>0</ixz>
          <iyy>0.01</iyy>
          <iyz>0</iyz>ujn
          <izz>0.005</izz>
        </inertia>
      </inertial>
    </link>

    <!-- Back Left Wheel -->
    <link name="wheel_bl">
      <visual name="wheel_bl_visual">
        <geometry>
          <mesh>
            <uri>file:///home/ruben/Documents/ProjetoFinal/roboauto/models/robo_camuflado/meshes/wheel_bl.dae</uri>
            <scale>1 1 1</scale>
          </mesh>
        </geometry>
      </visual>
      <collision name="wheel_bl_collision">
        <geometry>
          <cylinder>
            <radius>0.3</radius>
            <length>0.1</length>
          </cylinder>
        </geometry>
        <surface>
  <friction>
    <ode>
      <mu>1.0</mu>
      <mu2>1.0</mu2>
    </ode>
  </friction>
</surface>
      </collision>
      <inertial>
        <mass>0.5</mass>
        <inertia>
          <ixx>0.01</ixx>
          <ixy>0</ixy>
          <ixz>0</ixz>
          <iyy>0.01</iyy>
          <iyz>0</iyz>
          <izz>0.005</izz>
        </inertia>
      </inertial>
    </link>

    <!-- Back Right Wheel -->
    <link name="wheel_br">
      <visual name="wheel_br_visual">
        <geometry>
          <mesh>
            <uri>file:///home/ruben/Documents/ProjetoFinal/roboauto/models/robo_camuflado/meshes/wheel_br.dae</uri>
            <scale>1 1 1</scale>
          </mesh>
        </geometry>
      </visual>
      <collision name="wheel_br_collision">
        <geometry>
          <cylinder>
            <radius>0.3</radius>
            <length>0.1</length>
          </cylinder>
        </geometry>
        <surface>
          <friction>
            <ode>
              <mu>1.0</mu>
              <mu2>1.0</mu2>
            </ode>
          </friction>
        </surface>
      </collision>
      <inertial>
        <mass>0.5</mass>
        <inertia>
          <ixx>0.01</ixx>
          <ixy>0</ixy>
          <ixz>0</ixz>
          <iyy>0.01</iyy>
          <iyz>0</iyz>
          <izz>0.005</izz>
        </inertia>
      </inertial>
    </link>

    <!-- Wheel Joints -->
    <joint name="wheel_fl_joint" type="revolute">
      <parent>base_link</parent>
      <child>wheel_fl</child>
      <axis>
        <xyz>0 1 0</xyz>
        <dynamics>
          <damping>0.5</damping>
        </dynamics>
      </axis>
      <pose>-0.15 0.15 0.3 0 0 0</pose> <!-- Adjust position as needed -->
    </joint>

    <joint name="wheel_fr_joint" type="revolute">
      <parent>base_link</parent>
      <child>wheel_fr</child>
      <axis>
        <xyz>0 1 0</xyz>
        <dynamics>
          <damping>0.5</damping>
        </dynamics>
      </axis>
      <pose>-0.15 -0.15 0.3 0 0 0</pose>
    </joint>

    <joint name="wheel_bl_joint" type="revolute">
      <parent>base_link</parent>
      <child>wheel_bl</child>
      <axis>
        <xyz>0 1 0</xyz>
        <dynamics>
          <damping>0.5</damping>
        </dynamics>
      </axis>
      <pose>0.15 0.15 0.3 0 0 0</pose>
    </joint>

    <joint name="wheel_br_joint" type="revolute">
      <parent>base_link</parent>
      <child>wheel_br</child>
      <axis>
        <xyz>0 1 0</xyz>
        <dynamics>
          <damping>0.5</damping>
        </dynamics> 
      </axis>
      <pose>0.15 -0.15 0.3 0 0 0</pose>
    </joint>

  <!-- Global odometer -->
    <plugin
      filename="ignition-gazebo-odometry-publisher-system"
      name="ignition::gazebo::systems::OdometryPublisher">
      <odom_publish_frequency>50</odom_publish_frequency>
      <odom_topic>/odom</odom_topic>
      <odom_frame>odom</odom_frame>
      <robot_base_frame>base_footprint</robot_base_frame>
      <tf_topic>/odom/tf</tf_topic>
    </plugin>

    <!-- Differential drive -->
    <plugin filename="libignition-gazebo-diff-drive-system.so" 
            name="ignition::gazebo::systems::DiffDrive">
      <left_joint>wheel_fl_joint</left_joint>
      <right_joint>wheel_fr_joint</right_joint>
      <wheel_separation>0.287</wheel_separation>
      <wheel_radius>0.3</wheel_radius>
      <topic>cmd_vel</topic>
    </plugin>

    <!-- Joint state publisher -->
    <plugin filename="libignition-gazebo-joint-state-publisher-system.so" 
      name="ignition::gazebo::systems::JointStatePublisher">
      <topic>joint_states</topic>
    </plugin>
  </model>
</sdf>
