<?xml version="1.0"?>
<robot xmlns:xacro="http://ros.org/wiki/xacro" name="robo_camuflado">

  <!-- Base Footprint (frame) -->
  <link name="base_footprint" />

  <!-- Base Link -->
  <link name="base_link">
    <inertial>
      <origin xyz="-0.064 0 0.048" rpy="0 0 0"/>
      <mass value="1.3729096"/>
      <inertia
        ixx="0.042111447"
        ixy="0" ixz="0"
        iyy="0.042111447"
        iyz="0"
        izz="0.075254874"/>
    </inertial>
    <collision name="base_collision">
      <origin xyz="-0.064 0 0.048" rpy="0 0 0"/>
      <geometry>
        <box size="0.265 0.265 0.089"/>
      </geometry>
    </collision>
    <visual name="base_visual">
      <origin xyz="-0.064 0 0" rpy="0 0 0"/>
      <geometry>
        <mesh filename="package://turtlebot3/meshes/waffle_base.dae" scale="0.001 0.001 0.001"/>
      </geometry>
      <material name="base_material">
        <color rgba="0.921568627 0.925490196 0.941176471 1"/>
      </material>
    </visual>
  </link>

  <!-- Joint base_joint (fixed) -->
  <joint name="base_joint" type="fixed">
    <origin xyz="0 0 0.01" rpy="0 0 0"/>
    <parent link="base_footprint"/>
    <child link="base_link"/>
  </joint>

  <!-- IMU Link -->
  <link name="imu_link">
    <!-- Sensor não faz parte da definição URDF; para simulação deve usar plugins ou arquivos separados -->
  </link>

  <!-- Joint imu_joint (fixed) -->
  <joint name="imu_joint" type="fixed">
    <origin xyz="-0.032 0 0.068" rpy="0 0 0"/>
    <parent link="base_link"/>
    <child link="imu_link"/>
  </joint>

  <!-- LIDAR Link -->
  <link name="base_scan">
    <inertial>
      <origin xyz="-0.052 0 0.111" rpy="0 0 0"/>
      <mass value="0.114"/>
      <inertia
        ixx="0.001" ixy="0" ixz="0"
        iyy="0.001" iyz="0"
        izz="0.001"/>
    </inertial>
    <collision name="lidar_sensor_collision">
      <origin xyz="-0.052 0 0.111" rpy="0 0 0"/>
      <geometry>
        <cylinder radius="0.0508" length="0.055"/>
      </geometry>
    </collision>
    <visual name="lidar_sensor_visual">
      <origin xyz="-0.064 0 0.121" rpy="0 0 0"/>
      <geometry>
        <mesh filename="package://turtlebot3/meshes/lds.dae" scale="0.001 0.001 0.001"/>
      </geometry>
      <material name="lidar_material">
        <color rgba="0.145098039 0.156862745 0.164705882 1"/>
      </material>
    </visual>
  </link>

  <!-- Joint lidar_joint (fixed) -->
  <joint name="lidar_joint" type="fixed">
    <origin xyz="-0.064 0 0.121" rpy="0 0 0"/>
    <parent link="base_link"/>
    <child link="base_scan"/>
  </joint>

  <!-- Wheel left link -->
  <link name="wheel_left_link">
    <inertial>
      <origin xyz="0 0.144 0.023" rpy="-1.57 0 0"/>
      <mass value="0.1"/>
      <inertia
        ixx="1.1175580e-05" ixy="-4.2369783e-11" ixz="-5.9381719e-09"
        iyy="1.1192413e-05" iyz="-1.4400107e-11"
        izz="2.0712558e-05"/>
    </inertial>
    <collision name="wheel_left_collision">
      <origin xyz="0 0.144 0.023" rpy="-1.57 0 0"/>
      <geometry>
        <cylinder radius="0.033" length="0.018"/>
      </geometry>
      <!-- Friction e contact parameters não são padrão URDF, usados em SDF/simuladores -->
    </collision>
    <visual name="wheel_left_visual">
      <origin xyz="0 0.144 0.023" rpy="0 0 0"/>
      <geometry>
        <mesh filename="package://turtlebot3/meshes/tire.dae" scale="0.001 0.001 0.001"/>
      </geometry>
    </visual>
  </link>

  <!-- Joint wheel_left_joint (continuous) -->
  <joint name="wheel_left_joint" type="continuous">
    <origin xyz="0 0.144 0" rpy="0 0 0"/>
    <parent link="base_link"/>
    <child link="wheel_left_link"/>
    <axis xyz="0 1 0"/>
    <limit effort="5" velocity="10" lower="-10000" upper="10000"/>
    <dynamics damping="0.7"/>
  </joint>

  <!-- Wheel right link -->
  <link name="wheel_right_link">
    <inertial>
      <origin xyz="0 -0.144 0.023" rpy="-1.57 0 0"/>
      <mass value="0.1"/>
      <inertia
        ixx="1.1175580e-05" ixy="-4.2369783e-11" ixz="-5.9381719e-09"
        iyy="1.1192413e-05" iyz="-1.4400107e-11"
        izz="2.0712558e-05"/>
    </inertial>
    <collision name="wheel_right_collision">
      <origin xyz="0 -0.144 0.023" rpy="-1.57 0 0"/>
      <geometry>
        <cylinder radius="0.033" length="0.018"/>
      </geometry>
    </collision>
    <visual name="wheel_right_visual">
      <origin xyz="0 -0.144 0.023" rpy="0 0 0"/>
      <geometry>
        <mesh filename="package://turtlebot3/meshes/tire.dae" scale="0.001 0.001 0.001"/>
      </geometry>
    </visual>
  </link>

  <!-- Joint wheel_right_joint (continuous) -->
  <joint name="wheel_right_joint" type="continuous">
    <origin xyz="0 -0.144 0" rpy="0 0 0"/>
    <parent link="base_link"/>
    <child link="wheel_right_link"/>
    <axis xyz="0 1 0"/>
    <limit effort="5" velocity="10" lower="-10000" upper="10000"/>
    <dynamics damping="0.7"/>
  </joint>

</robot>

