<?xml version="1.0"?>
<sdf version="1.7">
  <model name="robo_camuflado">
    <!-- Base Link -->
    <link name="base_link">
      <visual name="base_visual">
        <geometry>
          <mesh>
            <uri>file:///home/ruben/Documents/ProjetoFinal/veiculo_terrestre/meshes/NOVO_ROBO/base_link.dae</uri>
            <scale>1 1 1</scale>
          </mesh>
        </geometry>
      </visual>
      <collision name="base_collision">
        <geometry>
          <box>
            <size>0.5 0.3 0.2</size> <!-- Adjust to match your base dimensions -->
          </box>
        </geometry>
      </collision>
      <inertial>
        <mass>5.0</mass> <!-- Adjust mass as needed -->
        <inertia>
          <ixx>0.1</ixx>
          <ixy>0</ixy>
          <ixz>0</ixz>
          <iyy>0.1</iyy>
          <iyz>0</iyz>
          <izz>0.1</izz>
        </inertia>
      </inertial>
    </link>

    <!-- Camera Link -->
    <link name="cam_link">
      <visual name="cam_visual">
        <geometry>
          <mesh>
            <uri>file:///home/ruben/Documents/ProjetoFinal/veiculo_terrestre/meshes/NOVO_ROBO/cam_link.dae</uri>
            <scale>1 1 1</scale>
          </mesh>
        </geometry>
      </visual>
      <inertial>
        <mass>0.1</mass>
        <inertia>
          <ixx>0.0001</ixx>
          <ixy>0</ixy>
          <ixz>0</ixz>
          <iyy>0.0001</iyy>
          <iyz>0</iyz>
          <izz>0.0001</izz>
        </inertia>
      </inertial>
    </link>

    <!-- Camera Joint -->
    <joint name="cam_joint" type="fixed">
      <parent>base_link</parent>
      <child>cam_link</child>
      <pose>0.2 0 0.15 0 0 0</pose> <!-- Adjust position as needed -->
    </joint>

    <!-- LiDAR Link -->
    <link name="lidar_link">
      <visual name="lidar_visual">
        <geometry>
          <mesh>
            <uri>file:///home/ruben/Documents/ProjetoFinal/veiculo_terrestre/meshes/NOVO_ROBO/lidar_link.dae</uri>
            <scale>1 1 1</scale>
          </mesh>
        </geometry>
      </visual>
      <inertial>
        <mass>0.2</mass>
        <inertia>
          <ixx>0.0002</ixx>
          <ixy>0</ixy>
          <ixz>0</ixz>
          <iyy>0.0002</iyy>
          <iyz>0</iyz>
          <izz>0.0002</izz>
        </inertia>
      </inertial>
    </link>

    <!-- LiDAR Joint -->
    <joint name="lidar_joint" type="fixed">
      <parent>base_link</parent>
      <child>lidar_link</child>
      <pose>0 0 0.2 0 0 0</pose> <!-- Adjust position as needed -->
    </joint>

    <!-- Front Left Wheel -->
    <link name="wheel_fl">
      <visual name="wheel_fl_visual">
        <geometry>
          <mesh>
            <uri>file:///home/ruben/Documents/ProjetoFinal/veiculo_terrestre/meshes/NOVO_ROBO/wheel_fl.dae</uri>
            <scale>1 1 1</scale>
          </mesh>
        </geometry>
      </visual>
      <collision name="wheel_fl_collision">
        <geometry>
          <cylinder>
            <radius>0.1</radius> <!-- Adjust to match your wheel size -->
            <length>0.05</length>
          </cylinder>
        </geometry>
      </collision>
      <inertial>
        <mass>0.5</mass>
        <inertia>
          <ixx>0.01</ixx>
          <ixy>0</ixy>
          <ixz>0</ixz>
          <iyy>0.01</iyy>
          <iyz>0</iyz>
          <izz>0.005</izz>
        </inertia>
      </inertial>
    </link>

    <!-- Front Right Wheel -->
    <link name="wheel_fr">
      <visual name="wheel_fr_visual">
        <geometry>
          <mesh>
            <uri>file:///home/ruben/Documents/ProjetoFinal/veiculo_terrestre/meshes/NOVO_ROBO/wheel_fr.dae</uri>
            <scale>1 1 1</scale>
          </mesh>
        </geometry>
      </visual>
      <collision name="wheel_fr_collision">
        <geometry>
          <cylinder>
            <radius>0.1</radius>
            <length>0.05</length>
          </cylinder>
        </geometry>
      </collision>
      <inertial>
        <mass>0.5</mass>
        <inertia>
          <ixx>0.01</ixx>
          <ixy>0</ixy>
          <ixz>0</ixz>
          <iyy>0.01</iyy>
          <iyz>0</iyz>
          <izz>0.005</izz>
        </inertia>
      </inertial>
    </link>

    <!-- Back Left Wheel -->
    <link name="wheel_bl">
      <visual name="wheel_bl_visual">
        <geometry>
          <mesh>
            <uri>file:///home/ruben/Documents/ProjetoFinal/veiculo_terrestre/meshes/NOVO_ROBO/wheel_bl.dae</uri>
            <scale>1 1 1</scale>
          </mesh>
        </geometry>
      </visual>
      <collision name="wheel_bl_collision">
        <geometry>
          <cylinder>
            <radius>0.1</radius>
            <length>0.05</length>
          </cylinder>
        </geometry>
      </collision>
      <inertial>
        <mass>0.5</mass>
        <inertia>
          <ixx>0.01</ixx>
          <ixy>0</ixy>
          <ixz>0</ixz>
          <iyy>0.01</iyy>
          <iyz>0</iyz>
          <izz>0.005</izz>
        </inertia>
      </inertial>
    </link>

    <!-- Back Right Wheel -->
    <link name="wheel_br">
      <visual name="wheel_br_visual">
        <geometry>
          <mesh>
            <uri>file:///home/ruben/Documents/ProjetoFinal/veiculo_terrestre/meshes/NOVO_ROBO/wheel_br.dae</uri>
            <scale>1 1 1</scale>
          </mesh>
        </geometry>
      </visual>
      <collision name="wheel_br_collision">
        <geometry>
          <cylinder>
            <radius>0.1</radius>
            <length>0.05</length>
          </cylinder>
        </geometry>
      </collision>
      <inertial>
        <mass>0.5</mass>
        <inertia>
          <ixx>0.01</ixx>
          <ixy>0</ixy>
          <ixz>0</ixz>
          <iyy>0.01</iyy>
          <iyz>0</iyz>
          <izz>0.005</izz>
        </inertia>
      </inertial>
    </link>

    <!-- Wheel Joints -->
    <joint name="wheel_fl_joint" type="revolute">
      <parent>base_link</parent>
      <child>wheel_fl</child>
      <axis>
        <xyz>0 1 0</xyz>
        <limit>
          <lower>-1e+16</lower>
          <upper>1e+16</upper>
        </limit>
      </axis>
      <pose>-0.15 0.15 -0.1 0 0 0</pose> <!-- Adjust position as needed -->
    </joint>

    <joint name="wheel_fr_joint" type="revolute">
      <parent>base_link</parent>
      <child>wheel_fr</child>
      <axis>
        <xyz>0 1 0</xyz>
        <limit>
          <lower>-1e+16</lower>
          <upper>1e+16</upper>
        </limit>
      </axis>
      <pose>-0.15 -0.15 -0.1 0 0 0</pose>
    </joint>

    <joint name="wheel_bl_joint" type="revolute">
      <parent>base_link</parent>
      <child>wheel_bl</child>
      <axis>
        <xyz>0 1 0</xyz>
        <limit>
          <lower>-1e+16</lower>
          <upper>1e+16</upper>
        </limit>
      </axis>
      <pose>0.15 0.15 -0.1 0 0 0</pose>
    </joint>

    <joint name="wheel_br_joint" type="revolute">
      <parent>base_link</parent>
      <child>wheel_br</child>
      <axis>
        <xyz>0 1 0</xyz>
        <limit>
          <lower>-1e+16</lower>
          <upper>1e+16</upper>
        </limit>
      </axis>
      <pose>0.15 -0.15 -0.1 0 0 0</pose>
    </joint>

    <!-- Plugin for skid steering drive -->
    <plugin name="skid_steer_drive" filename="libgazebo_ros_skid_steer_drive.so">
      <updateRate>100.0</updateRate>
      <robotNamespace>/</robotNamespace>
      <leftFrontJoint>wheel_fl_joint</leftFrontJoint>
      <rightFrontJoint>wheel_fr_joint</rightFrontJoint>
      <leftRearJoint>wheel_bl_joint</leftRearJoint>
      <rightRearJoint>wheel_br_joint</rightRearJoint>
      <wheelSeparation>0.3</wheelSeparation> <!-- Distance between wheels -->
      <wheelDiameter>0.2</wheelDiameter> <!-- 2 * wheel radius -->
      <robotBaseFrame>base_link</robotBaseFrame>
      <torque>20</torque>
      <topicName>cmd_vel</topicName>
      <broadcastTF>1</broadcastTF>
    </plugin>
  </model>
</sdf>
