<?xml version="1.0"?>
<robot xmlns:xacro="http://ros.org/wiki/xacro" name="robo_camuflado">

  <!-- Base Link -->
  <link name="base_link">
    <visual>
      <geometry>
        <mesh filename="package://turtlebot3/models/robo_camuflado/meshes/base_link.dae" scale="1 1 1"/>
      </geometry>
    </visual>
    <collision>
      <geometry>
        <box size="0.5 0.3 0.2"/>
      </geometry>
    </collision>
    <inertial>
      <mass value="5.0"/>
      <inertia 
        ixx="0.1" ixy="0.0" ixz="0.0" 
        iyy="0.1" iyz="0.0" 
        izz="0.1"/>
    </inertial>
  </link>

  <!-- Camera Link -->
  <link name="cam_link">
    <visual>
      <geometry>
        <mesh filename="package://turtlebot3/models/robo_camuflado/meshes/cam_link.dae" scale="1 1 1"/>
      </geometry>
    </visual>
    <inertial>
      <mass value="0.1"/>
      <inertia 
        ixx="0.0001" ixy="0.0" ixz="0.0"
        iyy="0.0001" iyz="0.0"
        izz="0.0001"/>
    </inertial>
  </link>

  <!-- Camera Joint -->
  <joint name="cam_joint" type="fixed">
    <parent link="base_link"/>
    <child link="cam_link"/>
    <origin xyz="0.2 0 0.15" rpy="0 0 0"/>
  </joint>

  <!-- LiDAR Link -->
  <link name="lidar_link">
    <visual>
      <geometry>
        <mesh filename="package://turtlebot3/models/robo_camuflado/meshes/lidar_link.dae" scale="1 1 1"/>
      </geometry>
    </visual>
    <inertial>
      <mass value="0.2"/>
      <inertia 
        ixx="0.0002" ixy="0.0" ixz="0.0"
        iyy="0.0002" iyz="0.0"
        izz="0.0002"/>
    </inertial>
  </link>

  <!-- LiDAR Joint -->
  <joint name="lidar_joint" type="fixed">
    <parent link="base_link"/>
    <child link="lidar_link"/>
    <origin xyz="0 0 0.2" rpy="0 0 0"/>
  </joint>

  <!-- Wheels -->
  <link name="wheel_fl">
    <visual>
      <geometry>
        <mesh filename="package://turtlebot3/models/robo_camuflado/meshes/wheel_fl.dae" scale="1 1 1"/>
      </geometry>
    </visual>
    <collision>
      <geometry>
        <cylinder radius="0.1" length="0.05"/>
      </geometry>
    </collision>
    <inertial>
      <mass value="0.5"/>
      <inertia 
        ixx="0.01" ixy="0.0" ixz="0.0"
        iyy="0.01" iyz="0.0"
        izz="0.005"/>
    </inertial>
  </link>

  <link name="wheel_fr">
    <visual>
      <geometry>
        <mesh filename="package://turtlebot3/models/robo_camuflado/meshes/wheel_fr.dae" scale="1 1 1"/>
      </geometry>
    </visual>
    <collision>
      <geometry>
        <cylinder radius="0.1" length="0.05"/>
      </geometry>
    </collision>
    <inertial>
      <mass value="0.5"/>
      <inertia 
        ixx="0.01" ixy="0.0" ixz="0.0"
        iyy="0.01" iyz="0.0"
        izz="0.005"/>
    </inertial>
  </link>

  <link name="wheel_bl">
    <visual>
      <geometry>
        <mesh filename="package://turtlebot3/models/robo_camuflado/meshes/wheel_bl.dae" scale="1 1 1"/>
      </geometry>
    </visual>
    <collision>
      <geometry>
        <cylinder radius="0.1" length="0.05"/>
      </geometry>
    </collision>
    <inertial>
      <mass value="0.5"/>
      <inertia 
        ixx="0.01" ixy="0.0" ixz="0.0"
        iyy="0.01" iyz="0.0"
        izz="0.005"/>
    </inertial>
  </link>

  <link name="wheel_br">
    <visual>
      <geometry>
        <mesh filename="package://turtlebot3/models/robo_camuflado/meshes/wheel_br.dae" scale="1 1 1"/>
      </geometry>
    </visual>
    <collision>
      <geometry>
        <cylinder radius="0.1" length="0.05"/>
      </geometry>
    </collision>
    <inertial>
      <mass value="0.5"/>
      <inertia 
        ixx="0.01" ixy="0.0" ixz="0.0"
        iyy="0.01" iyz="0.0"
        izz="0.005"/>
    </inertial>
  </link>

  <!-- Wheel Joints -->
  <joint name="wheel_fl_joint" type="revolute">
    <parent link="base_link"/>
    <child link="wheel_fl"/>
    <origin xyz="-0.15 0.15 -0.1" rpy="0 0 0"/>
    <axis xyz="0 1 0"/>
    <limit lower="-10000000000000000" upper="10000000000000000"/>
  </joint>

  <joint name="wheel_fr_joint" type="revolute">
    <parent link="base_link"/>
    <child link="wheel_fr"/>
    <origin xyz="-0.15 -0.15 -0.1" rpy="0 0 0"/>
    <axis xyz="0 1 0"/>
    <limit lower="-10000000000000000" upper="10000000000000000"/>
  </joint>

  <joint name="wheel_bl_joint" type="revolute">
    <parent link="base_link"/>
    <child link="wheel_bl"/>
    <origin xyz="0.15 0.15 -0.1" rpy="0 0 0"/>
    <axis xyz="0 1 0"/>
    <limit lower="-10000000000000000" upper="10000000000000000"/>
  </joint>

  <joint name="wheel_br_joint" type="revolute">
    <parent link="base_link"/>
    <child link="wheel_br"/>
    <origin xyz="0.15 -0.15 -0.1" rpy="0 0 0"/>
    <axis xyz="0 1 0"/>
    <limit lower="-10000000000000000" upper="10000000000000000"/>
  </joint>

</robot>

